Workbook

Sheet Instrucciones
A1: Planilla de comparación · Programa de validación de N25 Valves Sizing
A2: INSTRUMATIK S.A.S.
A4: 1. Abra en N25 Valves Sizing cada caso de la carpeta «casos» (Inicio > Abrir proyecto) y verifique que obtiene los valores de la hoja «Comparación».
A5: 2. Ingrese los mismos datos en su software de referencia (Fisher, Masoneilan, Conval, etc.). Use los mismos FL, xT y Fd, diámetros y cédulas.
A6: 3. Escriba el resultado de su software en la columna amarilla «Software de referencia». La diferencia y el estado se calculan solos.
A7: 4. Agregue sus propios casos reales en la hoja «Casos propios» (con el proyecto .valvula guardado desde N25 Valves Sizing).
A8: 5. Anote cualquier error, duda o mejora en la hoja «Hallazgos».
A9: 6. Envíe esta planilla, los proyectos .valvula y las capturas que considere útiles desde Ayuda > Enviar comentarios.
A11: Estado: «OK» si la diferencia está dentro de la tolerancia de la hoja «Tolerancias», «Revisar» si la supera.
A12: Una diferencia grande no siempre es un error: anote en «Observaciones» qué factor o propiedad usó su software.

Sheet Comparación
A1: Caso | B1: Condición | C1: Variable | D1: Unidad | E1: N25 Valves Sizing | F1: Software de referencia | G1: Nombre del software | H1: Diferencia | I1: Tolerancia | J1: Estado | K1: Observaciones
A2: Caso 1 · Líquido (IEC ej. 1) | B2: Normal | C2: Coeficiente de flujo (Cv) | E2: 190.8 | H2: =IF(F2="","",(F2-E2)/E2) | I2: =IF(Tolerancias!C2="","",Tolerancias!C2) | J2: =IF(OR(F2="",I2=""),"",IF(ABS(H2)*100<=I2,"OK","Revisar")) | K2: Norma IEC 60534-2-1 ej. 1: Kv = 165 (Cv = 190,7)
A3: Caso 1 · Líquido (IEC ej. 1) | B3: Normal | C3: ΔP para flujo estrangulado (ΔP choked) | D3: bar | E3: 4.966 | H3: =IF(F3="","",(F3-E3)/E3) | I3: =IF(Tolerancias!C4="","",Tolerancias!C4) | J3: =IF(OR(F3="",I3=""),"",IF(ABS(H3)*100<=I3,"OK","Revisar"))
A4: Caso 1 · Líquido (IEC ej. 1) | B4: Normal | C4: Factor de corrección por tuberías (Fp) | E4: 1 | H4: =IF(F4="","",(F4-E4)/E4) | I4: =IF(Tolerancias!C5="","",Tolerancias!C5) | J4: =IF(OR(F4="",I4=""),"",IF(ABS(H4)*100<=I4,"OK","Revisar"))
A5: Caso 1 · Líquido (IEC ej. 1) | B5: Normal | C5: Presión diferencial ΔP | D5: bar | E5: 4.6 | H5: =IF(F5="","",(F5-E5)/E5) | I5: =IF(Tolerancias!C6="","",Tolerancias!C6) | J5: =IF(OR(F5="",I5=""),"",IF(ABS(H5)*100<=I5,"OK","Revisar"))
A6: Caso 1 · Líquido (IEC ej. 1) | B6: Normal | C6: Apertura estimada | D6: % | E6: 81.3 | H6: =IF(F6="","",F6-E6) | I6: =IF(Tolerancias!C7="","",Tolerancias!C7) | J6: =IF(OR(F6="",I6=""),"",IF(ABS(H6)<=I6,"OK","Revisar"))
A7: Caso 1 · Líquido (IEC ej. 1) | B7: Normal | C7: Presión sonora a 1 m (LpAe,1m) | D7: dB(A) | E7: 80.3 | H7: =IF(F7="","",F7-E7) | I7: =IF(Tolerancias!C8="","",Tolerancias!C8) | J7: =IF(OR(F7="",I7=""),"",IF(ABS(H7)<=I7,"OK","Revisar"))
A8: Caso 1 · Líquido (IEC ej. 1) | B8: Normal | C8: Número de Reynolds (Rev) | E8: 2969072 | H8: =IF(F8="","",(F8-E8)/E8) | I8: =IF(Tolerancias!C13="","",Tolerancias!C13) | J8: =IF(OR(F8="",I8=""),"",IF(ABS(H8)*100<=I8,"OK","Revisar"))
A9: Caso 2 · Gas CO2 (IEC ej. 3) | B9: Normal | C9: Coeficiente de flujo (Cv) | E9: 72.54 | H9: =IF(F9="","",(F9-E9)/E9) | I9: =IF(Tolerancias!C2="","",Tolerancias!C2) | J9: =IF(OR(F9="",I9=""),"",IF(ABS(H9)*100<=I9,"OK","Revisar")) | K9: Norma IEC 60534-2-1 ej. 3: Kv = 62,7 (Cv = 72,5)
A10: Caso 2 · Gas CO2 (IEC ej. 3) | B10: Normal | C10: Factor de expansión (Y) | E10: 0.674 | H10: =IF(F10="","",(F10-E10)/E10) | I10: =IF(Tolerancias!C3="","",Tolerancias!C3) | J10: =IF(OR(F10="",I10=""),"",IF(ABS(H10)*100<=I10,"OK","Revisar")) | K10: Norma IEC 60534-2-1 ej. 3: Y = 0,674
A11: Caso 2 · Gas CO2 (IEC ej. 3) | B11: Normal | C11: ΔP para flujo estrangulado (ΔP choked) | D11: bar | E11: 3.787 | H11: =IF(F11="","",(F11-E11)/E11) | I11: =IF(Tolerancias!C4="","",Tolerancias!C4) | J11: =IF(OR(F11="",I11=""),"",IF(ABS(H11)*100<=I11,"OK","Revisar"))
A12: Caso 2 · Gas CO2 (IEC ej. 3) | B12: Normal | C12: Factor de corrección por tuberías (Fp) | E12: 1 | H12: =IF(F12="","",(F12-E12)/E12) | I12: =IF(Tolerancias!C5="","",Tolerancias!C5) | J12: =IF(OR(F12="",I12=""),"",IF(ABS(H12)*100<=I12,"OK","Revisar"))
A13: Caso 2 · Gas CO2 (IEC ej. 3) | B13: Normal | C13: Presión diferencial ΔP | D13: bar | E13: 3.7 | H13: =IF(F13="","",(F13-E13)/E13) | I13: =IF(Tolerancias!C6="","",Tolerancias!C6) | J13: =IF(OR(F13="",I13=""),"",IF(ABS(H13)*100<=I13,"OK","Revisar"))
A14: Caso 2 · Gas CO2 (IEC ej. 3) | B14: Normal | C14: Apertura estimada | D14: % | E14: 77.3 | H14: =IF(F14="","",F14-E14) | I14: =IF(Tolerancias!C7="","",Tolerancias!C7) | J14: =IF(OR(F14="",I14=""),"",IF(ABS(H14)<=I14,"OK","Revisar"))
A15: Caso 2 · Gas CO2 (IEC ej. 3) | B15: Normal | C15: Ruido de la válvula LpA a 1 m | D15: dB(A) | E15: 96.6 | H15: =IF(F15="","",F15-E15) | I15: =IF(Tolerancias!C9="","",Tolerancias!C9) | J15: =IF(OR(F15="",I15=""),"",IF(ABS(H15)<=I15,"OK","Revisar"))
A16: Caso 2 · Gas CO2 (IEC ej. 3) | B16: Normal | C16: Mach en la salida de la válvula | E16: 0.206 | H16: =IF(F16="","",(F16-E16)/E16) | I16: =IF(Tolerancias!C10="","",Tolerancias!C10) | J16: =IF(OR(F16="",I16=""),"",IF(ABS(H16)*100<=I16,"OK","Revisar"))
A17: Caso 2 · Gas CO2 (IEC ej. 3) | B17: Normal | C17: Velocidad en la salida de la válvula | D17: m/s | E17: 66.7 | H17: =IF(F17="","",(F17-E17)/E17) | I17: =IF(Tolerancias!C11="","",Tolerancias!C11) | J17: =IF(OR(F17="",I17=""),"",IF(ABS(H17)*100<=I17,"OK","Revisar"))
A18: Caso 2 · Gas CO2 (IEC ej. 3) | B18: Normal | C18: Número de Reynolds (Rev) | E18: 1915696 | H18: =IF(F18="","",(F18-E18)/E18) | I18: =IF(Tolerancias!C13="","",Tolerancias!C13) | J18: =IF(OR(F18="",I18=""),"",IF(ABS(H18)*100<=I18,"OK","Revisar"))
A19: Caso 3 · Gas natural | B19: Mínimo | C19: Coeficiente de flujo (Cv) | E19: 19.78 | H19: =IF(F19="","",(F19-E19)/E19) | I19: =IF(Tolerancias!C2="","",Tolerancias!C2) | J19: =IF(OR(F19="",I19=""),"",IF(ABS(H19)*100<=I19,"OK","Revisar"))
A20: Caso 3 · Gas natural | B20: Normal | C20: Coeficiente de flujo (Cv) | E20: 44.1 | H20: =IF(F20="","",(F20-E20)/E20) | I20: =IF(Tolerancias!C2="","",Tolerancias!C2) | J20: =IF(OR(F20="",I20=""),"",IF(ABS(H20)*100<=I20,"OK","Revisar"))
A21: Caso 3 · Gas natural | B21: Máximo | C21: Coeficiente de flujo (Cv) | E21: 65.57 | H21: =IF(F21="","",(F21-E21)/E21) | I21: =IF(Tolerancias!C2="","",Tolerancias!C2) | J21: =IF(OR(F21="",I21=""),"",IF(ABS(H21)*100<=I21,"OK","Revisar"))
A22: Caso 3 · Gas natural | B22: Mínimo | C22: Factor de expansión (Y) | E22: 0.886 | H22: =IF(F22="","",(F22-E22)/E22) | I22: =IF(Tolerancias!C3="","",Tolerancias!C3) | J22: =IF(OR(F22="",I22=""),"",IF(ABS(H22)*100<=I22,"OK","Revisar"))
A23: Caso 3 · Gas natural | B23: Normal | C23: Factor de expansión (Y) | E23: 0.808 | H23: =IF(F23="","",(F23-E23)/E23) | I23: =IF(Tolerancias!C3="","",Tolerancias!C3) | J23: =IF(OR(F23="",I23=""),"",IF(ABS(H23)*100<=I23,"OK","Revisar"))
A24: Caso 3 · Gas natural | B24: Máximo | C24: Factor de expansión (Y) | E24: 0.734 | H24: =IF(F24="","",(F24-E24)/E24) | I24: =IF(Tolerancias!C3="","",Tolerancias!C3) | J24: =IF(OR(F24="",I24=""),"",IF(ABS(H24)*100<=I24,"OK","Revisar"))
A25: Caso 3 · Gas natural | B25: Mínimo | C25: ΔP para flujo estrangulado (ΔP choked) | D25: bar | E25: 29.32 | H25: =IF(F25="","",(F25-E25)/E25) | I25: =IF(Tolerancias!C4="","",Tolerancias!C4) | J25: =IF(OR(F25="",I25=""),"",IF(ABS(H25)*100<=I25,"OK","Revisar"))
A26: Caso 3 · Gas natural | B26: Normal | C26: ΔP para flujo estrangulado (ΔP choked) | D26: bar | E26: 27.83 | H26: =IF(F26="","",(F26-E26)/E26) | I26: =IF(Tolerancias!C4="","",Tolerancias!C4) | J26: =IF(OR(F26="",I26=""),"",IF(ABS(H26)*100<=I26,"OK","Revisar"))
A27: Caso 3 · Gas natural | B27: Máximo | C27: ΔP para flujo estrangulado (ΔP choked) | D27: bar | E27: 26.34 | H27: =IF(F27="","",(F27-E27)/E27) | I27: =IF(Tolerancias!C4="","",Tolerancias!C4) | J27: =IF(OR(F27="",I27=""),"",IF(ABS(H27)*100<=I27,"OK","Revisar"))
A28: Caso 3 · Gas natural | B28: Mínimo | C28: Factor de corrección por tuberías (Fp) | E28: 0.999 | H28: =IF(F28="","",(F28-E28)/E28) | I28: =IF(Tolerancias!C5="","",Tolerancias!C5) | J28: =IF(OR(F28="",I28=""),"",IF(ABS(H28)*100<=I28,"OK","Revisar"))
A29: Caso 3 · Gas natural | B29: Normal | C29: Factor de corrección por tuberías (Fp) | E29: 0.997 | H29: =IF(F29="","",(F29-E29)/E29) | I29: =IF(Tolerancias!C5="","",Tolerancias!C5) | J29: =IF(OR(F29="",I29=""),"",IF(ABS(H29)*100<=I29,"OK","Revisar"))
A30: Caso 3 · Gas natural | B30: Máximo | C30: Factor de corrección por tuberías (Fp) | E30: 0.994 | H30: =IF(F30="","",(F30-E30)/E30) | I30: =IF(Tolerancias!C5="","",Tolerancias!C5) | J30: =IF(OR(F30="",I30=""),"",IF(ABS(H30)*100<=I30,"OK","Revisar"))
A31: Caso 3 · Gas natural | B31: Mínimo | C31: Presión diferencial ΔP | D31: bar | E31: 10 | H31: =IF(F31="","",(F31-E31)/E31) | I31: =IF(Tolerancias!C6="","",Tolerancias!C6) | J31: =IF(OR(F31="",I31=""),"",IF(ABS(H31)*100<=I31,"OK","Revisar"))
A32: Caso 3 · Gas natural | B32: Normal | C32: Presión diferencial ΔP | D32: bar | E32: 16 | H32: =IF(F32="","",(F32-E32)/E32) | I32: =IF(Tolerancias!C6="","",Tolerancias!C6) | J32: =IF(OR(F32="",I32=""),"",IF(ABS(H32)*100<=I32,"OK","Revisar"))
A33: Caso 3 · Gas natural | B33: Máximo | C33: Presión diferencial ΔP | D33: bar | E33: 21 | H33: =IF(F33="","",(F33-E33)/E33) | I33: =IF(Tolerancias!C6="","",Tolerancias!C6) | J33: =IF(OR(F33="",I33=""),"",IF(ABS(H33)*100<=I33,"OK","Revisar"))
A34: Caso 3 · Gas natural | B34: Mínimo | C34: Apertura estimada | D34: % | E34: 44.1 | H34: =IF(F34="","",F34-E34) | I34: =IF(Tolerancias!C7="","",Tolerancias!C7) | J34: =IF(OR(F34="",I34=""),"",IF(ABS(H34)<=I34,"OK","Revisar"))
A35: Caso 3 · Gas natural | B35: Normal | C35: Apertura estimada | D35: % | E35: 64.6 | H35: =IF(F35="","",F35-E35) | I35: =IF(Tolerancias!C7="","",Tolerancias!C7) | J35: =IF(OR(F35="",I35=""),"",IF(ABS(H35)<=I35,"OK","Revisar"))
A36: Caso 3 · Gas natural | B36: Máximo | C36: Apertura estimada | D36: % | E36: 74.8 | H36: =IF(F36="","",F36-E36) | I36: =IF(Tolerancias!C7="","",Tolerancias!C7) | J36: =IF(OR(F36="",I36=""),"",IF(ABS(H36)<=I36,"OK","Revisar"))
A37: Caso 3 · Gas natural | B37: Mínimo | C37: Ruido de la válvula LpA a 1 m | D37: dB(A) | E37: 88.6 | H37: =IF(F37="","",F37-E37) | I37: =IF(Tolerancias!C9="","",Tolerancias!C9) | J37: =IF(OR(F37="",I37=""),"",IF(ABS(H37)<=I37,"OK","Revisar"))
A38: Caso 3 · Gas natural | B38: Normal | C38: Ruido de la válvula LpA a 1 m | D38: dB(A) | E38: 100 | H38: =IF(F38="","",F38-E38) | I38: =IF(Tolerancias!C9="","",Tolerancias!C9) | J38: =IF(OR(F38="",I38=""),"",IF(ABS(H38)<=I38,"OK","Revisar"))
A39: Caso 3 · Gas natural | B39: Máximo | C39: Ruido de la válvula LpA a 1 m | D39: dB(A) | E39: 107 | H39: =IF(F39="","",F39-E39) | I39: =IF(Tolerancias!C9="","",Tolerancias!C9) | J39: =IF(OR(F39="",I39=""),"",IF(ABS(H39)<=I39,"OK","Revisar"))
A40: Caso 3 · Gas natural | B40: Mínimo | C40: Mach en la salida de la válvula | E40: 0.0293 | H40: =IF(F40="","",(F40-E40)/E40) | I40: =IF(Tolerancias!C10="","",Tolerancias!C10) | J40: =IF(OR(F40="",I40=""),"",IF(ABS(H40)*100<=I40,"OK","Revisar"))
...

Sheet Tolerancias
A1: Clave | B1: Variable | C1: Tolerancia | D1: Unidad | E1: Comentario
A2: Cv | B2: Coeficiente de flujo Cv | C2: 2 | D2: % | E2: Con los mismos FL, xT, Fd y diámetros.
A3: Y | B3: Factor de expansión Y | C3: 1 | D3: % | E3: Gas, vapor y steam.
A4: dPchoked | B4: ΔP de flujo estrangulado | C4: 2 | D4: %
A5: FP | B5: Factor de tuberías Fp | C5: 1 | D5: % | E5: Con reductores la norma itera; hasta 1 % es normal.
A6: dP | B6: Presión diferencial | C6: 0.5 | D6: % | E6: Debe coincidir: es dato de entrada.
A7: apertura | B7: Apertura estimada | C7: 5 | D7: puntos | E7: Depende de la curva de cada fabricante; informativa.
A8: Lp | B8: Ruido LpA a 1 m (líquido) | C8: 3 | D8: dB | E8: IEC 60534-8-4; entre implementaciones 1 a 3 dB es normal.
A9: Lp_g | B9: Ruido LpA a 1 m (gas) | C9: 3 | D9: dB | E9: IEC 60534-8-3; verificar que el otro software use la misma norma.
A10: Ma_valvula | B10: Mach en la salida de la válvula | C10: 5 | D10: % | E10: Depende del área de salida considerada.
A11: v_valvula | B11: Velocidad en la salida de la válvula | C11: 5 | D11: %
A12: sobrecalentamiento2 | B12: Sobrecalentamiento a P2 | C12: 2 | D12: °C | E12: Steam (IAPWS-95).
A13: Rev | B13: Número de Reynolds | E13: Informativo: cada software usa una convención; no cambia el Cv si Rev > 10 000.

Sheet Casos propios
A1: Caso / tag | B1: Fluido | C1: Condición | D1: Variable | E1: Unidad | F1: N25 Valves Sizing | G1: Software de referencia | H1: Nombre del software | I1: Diferencia % | J1: Archivo .valvula | K1: Observaciones
I2: =IF(OR(F2="",G2=""),"",(G2-F2)/F2)
I3: =IF(OR(F3="",G3=""),"",(G3-F3)/F3)
I4: =IF(OR(F4="",G4=""),"",(G4-F4)/F4)
I5: =IF(OR(F5="",G5=""),"",(G5-F5)/F5)
I6: =IF(OR(F6="",G6=""),"",(G6-F6)/F6)
I7: =IF(OR(F7="",G7=""),"",(G7-F7)/F7)
I8: =IF(OR(F8="",G8=""),"",(G8-F8)/F8)
I9: =IF(OR(F9="",G9=""),"",(G9-F9)/F9)
I10: =IF(OR(F10="",G10=""),"",(G10-F10)/F10)
I11: =IF(OR(F11="",G11=""),"",(G11-F11)/F11)
I12: =IF(OR(F12="",G12=""),"",(G12-F12)/F12)
I13: =IF(OR(F13="",G13=""),"",(G13-F13)/F13)
... I101: =IF(OR(F101="",G101=""),"",(G101-F101)/F101)

Sheet Hallazgos
A1: N° | B1: Fecha | C1: Tipo | D1: Pantalla o documento | E1: Descripción | F1: Cómo reproducirlo | G1: Gravedad | H1: Captura / archivo
A2: 1
A3: 2
A4: 3
A5: 4
A6: 5
A7: 6
A8: 7
A9: 8
A10: 9
A11: 10
A12: 11
A13: 12
... A51: 50
