Workbook

Sheet Instrucciones
A1: Planilla de comparación · Workshop N25 Valves Sizing (24/10/2026)
A2: INSTRUMATIK S.A.S.
A4: 1. Abra en N25 Valves Sizing cada caso de la carpeta «2_Casos_del_workshop» (Inicio > Abrir proyecto) y verifique que obtiene los valores de la hoja «Comparación».
A5: 2. Ingrese los mismos datos en su software de referencia (Fisher, Masoneilan, Conval, etc.). Use los mismos FL, xT y Fd, diámetros y cédulas.
A6: 3. Escriba el resultado de su software en la columna amarilla «Software de referencia». La diferencia y el estado se calculan solos.
A7: 4. Agregue sus propios casos reales en la hoja «Casos propios» (con el proyecto .valvula guardado desde N25 Valves Sizing).
A8: 5. Anote cualquier error, duda o mejora en la hoja «Hallazgos».
A9: 6. Envíe esta planilla, los proyectos .valvula y las capturas que considere útiles desde Ayuda > Enviar comentarios.
A11: Estado: «OK» si la diferencia está dentro de la tolerancia de la hoja «Tolerancias», «Revisar» si la supera.
A12: Una diferencia grande no siempre es un error: anote en «Observaciones» qué factor o propiedad usó su software.

Sheet Comparación
A1: Caso | B1: Condición | C1: Variable | D1: Unidad | E1: N25 Valves Sizing | F1: Software de referencia | G1: Nombre del software | H1: Diferencia | I1: Tolerancia | J1: Estado | K1: Observaciones
A2: Caso A · Baja · Agua de enfriamiento | B2: Mínimo | C2: Coeficiente de flujo (Cv) | E2: 445.6 | H2: =IF(F2="","",(F2-E2)/E2) | I2: =IF(Tolerancias!C2="","",Tolerancias!C2) | J2: =IF(OR(F2="",I2=""),"",IF(ABS(H2)*100<=I2,"OK","Revisar"))
A3: Caso A · Baja · Agua de enfriamiento | B3: Normal | C3: Coeficiente de flujo (Cv) | E3: 679.1 | H3: =IF(F3="","",(F3-E3)/E3) | I3: =IF(Tolerancias!C2="","",Tolerancias!C2) | J3: =IF(OR(F3="",I3=""),"",IF(ABS(H3)*100<=I3,"OK","Revisar"))
A4: Caso A · Baja · Agua de enfriamiento | B4: Máximo | C4: Coeficiente de flujo (Cv) | E4: 1046 | H4: =IF(F4="","",(F4-E4)/E4) | I4: =IF(Tolerancias!C2="","",Tolerancias!C2) | J4: =IF(OR(F4="",I4=""),"",IF(ABS(H4)*100<=I4,"OK","Revisar"))
A5: Caso A · Baja · Agua de enfriamiento | B5: Mínimo | C5: ΔP crítica de flujo estrangulado (ΔP choked) | D5: bar | E5: 2.504 | H5: =IF(F5="","",(F5-E5)/E5) | I5: =IF(Tolerancias!C4="","",Tolerancias!C4) | J5: =IF(OR(F5="",I5=""),"",IF(ABS(H5)*100<=I5,"OK","Revisar"))
A6: Caso A · Baja · Agua de enfriamiento | B6: Normal | C6: ΔP crítica de flujo estrangulado (ΔP choked) | D6: bar | E6: 2.374 | H6: =IF(F6="","",(F6-E6)/E6) | I6: =IF(Tolerancias!C4="","",Tolerancias!C4) | J6: =IF(OR(F6="",I6=""),"",IF(ABS(H6)*100<=I6,"OK","Revisar"))
A7: Caso A · Baja · Agua de enfriamiento | B7: Máximo | C7: ΔP crítica de flujo estrangulado (ΔP choked) | D7: bar | E7: 2.201 | H7: =IF(F7="","",(F7-E7)/E7) | I7: =IF(Tolerancias!C4="","",Tolerancias!C4) | J7: =IF(OR(F7="",I7=""),"",IF(ABS(H7)*100<=I7,"OK","Revisar"))
A8: Caso A · Baja · Agua de enfriamiento | B8: Mínimo | C8: Factor de corrección por tuberías (Fp) | E8: 0.988 | H8: =IF(F8="","",(F8-E8)/E8) | I8: =IF(Tolerancias!C5="","",Tolerancias!C5) | J8: =IF(OR(F8="",I8=""),"",IF(ABS(H8)*100<=I8,"OK","Revisar"))
A9: Caso A · Baja · Agua de enfriamiento | B9: Normal | C9: Factor de corrección por tuberías (Fp) | E9: 0.972 | H9: =IF(F9="","",(F9-E9)/E9) | I9: =IF(Tolerancias!C5="","",Tolerancias!C5) | J9: =IF(OR(F9="",I9=""),"",IF(ABS(H9)*100<=I9,"OK","Revisar"))
A10: Caso A · Baja · Agua de enfriamiento | B10: Máximo | C10: Factor de corrección por tuberías (Fp) | E10: 0.937 | H10: =IF(F10="","",(F10-E10)/E10) | I10: =IF(Tolerancias!C5="","",Tolerancias!C5) | J10: =IF(OR(F10="",I10=""),"",IF(ABS(H10)*100<=I10,"OK","Revisar"))
A11: Caso A · Baja · Agua de enfriamiento | B11: Mínimo | C11: Presión diferencial ΔP | D11: bar | E11: 1.1 | H11: =IF(F11="","",(F11-E11)/E11) | I11: =IF(Tolerancias!C6="","",Tolerancias!C6) | J11: =IF(OR(F11="",I11=""),"",IF(ABS(H11)*100<=I11,"OK","Revisar"))
A12: Caso A · Baja · Agua de enfriamiento | B12: Normal | C12: Presión diferencial ΔP | D12: bar | E12: 1.1 | H12: =IF(F12="","",(F12-E12)/E12) | I12: =IF(Tolerancias!C6="","",Tolerancias!C6) | J12: =IF(OR(F12="",I12=""),"",IF(ABS(H12)*100<=I12,"OK","Revisar"))
A13: Caso A · Baja · Agua de enfriamiento | B13: Máximo | C13: Presión diferencial ΔP | D13: bar | E13: 1 | H13: =IF(F13="","",(F13-E13)/E13) | I13: =IF(Tolerancias!C6="","",Tolerancias!C6) | J13: =IF(OR(F13="",I13=""),"",IF(ABS(H13)*100<=I13,"OK","Revisar"))
A14: Caso A · Baja · Agua de enfriamiento | B14: Tight Shutoff | C14: Presión diferencial ΔP | D14: bar | E14: 6.8 | H14: =IF(F14="","",(F14-E14)/E14) | I14: =IF(Tolerancias!C6="","",Tolerancias!C6) | J14: =IF(OR(F14="",I14=""),"",IF(ABS(H14)*100<=I14,"OK","Revisar"))
A15: Caso A · Baja · Agua de enfriamiento | B15: Mínimo | C15: Apertura estimada | D15: % | E15: 57.1 | H15: =IF(F15="","",F15-E15) | I15: =IF(Tolerancias!C7="","",Tolerancias!C7) | J15: =IF(OR(F15="",I15=""),"",IF(ABS(H15)<=I15,"OK","Revisar"))
A16: Caso A · Baja · Agua de enfriamiento | B16: Normal | C16: Apertura estimada | D16: % | E16: 69.4 | H16: =IF(F16="","",F16-E16) | I16: =IF(Tolerancias!C7="","",Tolerancias!C7) | J16: =IF(OR(F16="",I16=""),"",IF(ABS(H16)<=I16,"OK","Revisar"))
A17: Caso A · Baja · Agua de enfriamiento | B17: Máximo | C17: Apertura estimada | D17: % | E17: 82.1 | H17: =IF(F17="","",F17-E17) | I17: =IF(Tolerancias!C7="","",Tolerancias!C7) | J17: =IF(OR(F17="",I17=""),"",IF(ABS(H17)<=I17,"OK","Revisar"))
A18: Caso A · Baja · Agua de enfriamiento | B18: Mínimo | C18: Presión sonora a 1 m (LpAe,1m) | D18: dB(A) | E18: 59.7 | H18: =IF(F18="","",F18-E18) | I18: =IF(Tolerancias!C8="","",Tolerancias!C8) | J18: =IF(OR(F18="",I18=""),"",IF(ABS(H18)<=I18,"OK","Revisar"))
A19: Caso A · Baja · Agua de enfriamiento | B19: Normal | C19: Presión sonora a 1 m (LpAe,1m) | D19: dB(A) | E19: 64.4 | H19: =IF(F19="","",F19-E19) | I19: =IF(Tolerancias!C8="","",Tolerancias!C8) | J19: =IF(OR(F19="",I19=""),"",IF(ABS(H19)<=I19,"OK","Revisar"))
A20: Caso A · Baja · Agua de enfriamiento | B20: Máximo | C20: Presión sonora a 1 m (LpAe,1m) | D20: dB(A) | E20: 67.9 | H20: =IF(F20="","",F20-E20) | I20: =IF(Tolerancias!C8="","",Tolerancias!C8) | J20: =IF(OR(F20="",I20=""),"",IF(ABS(H20)<=I20,"OK","Revisar"))
A21: Caso A · Baja · Agua de enfriamiento | B21: Mínimo | C21: Coef. cavitación de la aplicación (Kapp) | E21: 0.198 | H21: =IF(F21="","",(F21-E21)/E21) | I21: =IF(Tolerancias!C13="","",Tolerancias!C13) | J21: =IF(OR(F21="",I21=""),"",IF(ABS(H21)*100<=I21,"OK","Revisar"))
A22: Caso A · Baja · Agua de enfriamiento | B22: Normal | C22: Coef. cavitación de la aplicación (Kapp) | E22: 0.209 | H22: =IF(F22="","",(F22-E22)/E22) | I22: =IF(Tolerancias!C13="","",Tolerancias!C13) | J22: =IF(OR(F22="",I22=""),"",IF(ABS(H22)*100<=I22,"OK","Revisar"))
A23: Caso A · Baja · Agua de enfriamiento | B23: Máximo | C23: Coef. cavitación de la aplicación (Kapp) | E23: 0.206 | H23: =IF(F23="","",(F23-E23)/E23) | I23: =IF(Tolerancias!C13="","",Tolerancias!C13) | J23: =IF(OR(F23="",I23=""),"",IF(ABS(H23)*100<=I23,"OK","Revisar"))
A24: Caso A · Baja · Agua de enfriamiento | B24: Mínimo | C24: Inicio de cavitación incipiente (xFzp1) | E24: 0.14 | H24: =IF(F24="","",(F24-E24)/E24) | I24: =IF(Tolerancias!C14="","",Tolerancias!C14) | J24: =IF(OR(F24="",I24=""),"",IF(ABS(H24)*100<=I24,"OK","Revisar"))
A25: Caso A · Baja · Agua de enfriamiento | B25: Normal | C25: Inicio de cavitación incipiente (xFzp1) | E25: 0.128 | H25: =IF(F25="","",(F25-E25)/E25) | I25: =IF(Tolerancias!C14="","",Tolerancias!C14) | J25: =IF(OR(F25="",I25=""),"",IF(ABS(H25)*100<=I25,"OK","Revisar"))
A26: Caso A · Baja · Agua de enfriamiento | B26: Máximo | C26: Inicio de cavitación incipiente (xFzp1) | E26: 0.116 | H26: =IF(F26="","",(F26-E26)/E26) | I26: =IF(Tolerancias!C14="","",Tolerancias!C14) | J26: =IF(OR(F26="",I26=""),"",IF(ABS(H26)*100<=I26,"OK","Revisar"))
A27: Caso A · Baja · Agua de enfriamiento | B27: Mínimo | C27: Factor de recuperación combinado (FLp) | E27: 0.662 | H27: =IF(F27="","",(F27-E27)/E27) | I27: =IF(Tolerancias!C15="","",Tolerancias!C15) | J27: =IF(OR(F27="",I27=""),"",IF(ABS(H27)*100<=I27,"OK","Revisar"))
A28: Caso A · Baja · Agua de enfriamiento | B28: Normal | C28: Factor de recuperación combinado (FLp) | E28: 0.653 | H28: =IF(F28="","",(F28-E28)/E28) | I28: =IF(Tolerancias!C15="","",Tolerancias!C15) | J28: =IF(OR(F28="",I28=""),"",IF(ABS(H28)*100<=I28,"OK","Revisar"))
A29: Caso A · Baja · Agua de enfriamiento | B29: Máximo | C29: Factor de recuperación combinado (FLp) | E29: 0.631 | H29: =IF(F29="","",(F29-E29)/E29) | I29: =IF(Tolerancias!C15="","",Tolerancias!C15) | J29: =IF(OR(F29="",I29=""),"",IF(ABS(H29)*100<=I29,"OK","Revisar"))
A30: Caso A · Baja · Agua de enfriamiento | B30: Mínimo | C30: ΔP para cavitación (ΔP cav) | D30: bar | E30: 1.948 | H30: =IF(F30="","",(F30-E30)/E30) | I30: =IF(Tolerancias!C16="","",Tolerancias!C16) | J30: =IF(OR(F30="",I30=""),"",IF(ABS(H30)*100<=I30,"OK","Revisar"))
A31: Caso A · Baja · Agua de enfriamiento | B31: Normal | C31: ΔP para cavitación (ΔP cav) | D31: bar | E31: 1.843 | H31: =IF(F31="","",(F31-E31)/E31) | I31: =IF(Tolerancias!C16="","",Tolerancias!C16) | J31: =IF(OR(F31="",I31=""),"",IF(ABS(H31)*100<=I31,"OK","Revisar"))
A32: Caso A · Baja · Agua de enfriamiento | B32: Máximo | C32: ΔP para cavitación (ΔP cav) | D32: bar | E32: 1.7 | H32: =IF(F32="","",(F32-E32)/E32) | I32: =IF(Tolerancias!C16="","",Tolerancias!C16) | J32: =IF(OR(F32="",I32=""),"",IF(ABS(H32)*100<=I32,"OK","Revisar"))
A33: Caso A · Baja · Agua de enfriamiento | B33: Mínimo | C33: Densidad de entrada ρ1 | D33: kg/m³ | E33: 995.2 | H33: =IF(F33="","",(F33-E33)/E33) | I33: =IF(Tolerancias!C17="","",Tolerancias!C17) | J33: =IF(OR(F33="",I33=""),"",IF(ABS(H33)*100<=I33,"OK","Revisar"))
A34: Caso A · Baja · Agua de enfriamiento | B34: Normal | C34: Densidad de entrada ρ1 | D34: kg/m³ | E34: 995.2 | H34: =IF(F34="","",(F34-E34)/E34) | I34: =IF(Tolerancias!C17="","",Tolerancias!C17) | J34: =IF(OR(F34="",I34=""),"",IF(ABS(H34)*100<=I34,"OK","Revisar"))
A35: Caso A · Baja · Agua de enfriamiento | B35: Máximo | C35: Densidad de entrada ρ1 | D35: kg/m³ | E35: 994.2 | H35: =IF(F35="","",(F35-E35)/E35) | I35: =IF(Tolerancias!C17="","",Tolerancias!C17) | J35: =IF(OR(F35="",I35=""),"",IF(ABS(H35)*100<=I35,"OK","Revisar"))
A36: Caso A · Baja · Agua de enfriamiento | B36: Mínimo | C36: Velocidad del fluido aguas arriba | D36: m/s | E36: 1.52 | H36: =IF(F36="","",(F36-E36)/E36) | I36: =IF(Tolerancias!C20="","",Tolerancias!C20) | J36: =IF(OR(F36="",I36=""),"",IF(ABS(H36)*100<=I36,"OK","Revisar"))
A37: Caso A · Baja · Agua de enfriamiento | B37: Normal | C37: Velocidad del fluido aguas arriba | D37: m/s | E37: 2.29 | H37: =IF(F37="","",(F37-E37)/E37) | I37: =IF(Tolerancias!C20="","",Tolerancias!C20) | J37: =IF(OR(F37="",I37=""),"",IF(ABS(H37)*100<=I37,"OK","Revisar"))
A38: Caso A · Baja · Agua de enfriamiento | B38: Máximo | C38: Velocidad del fluido aguas arriba | D38: m/s | E38: 3.24 | H38: =IF(F38="","",(F38-E38)/E38) | I38: =IF(Tolerancias!C20="","",Tolerancias!C20) | J38: =IF(OR(F38="",I38=""),"",IF(ABS(H38)*100<=I38,"OK","Revisar"))
A39: Caso A · Baja · Agua de enfriamiento | B39: Mínimo | C39: Velocidad del fluido aguas abajo | D39: m/s | E39: 1.52 | H39: =IF(F39="","",(F39-E39)/E39) | I39: =IF(Tolerancias!C21="","",Tolerancias!C21) | J39: =IF(OR(F39="",I39=""),"",IF(ABS(H39)*100<=I39,"OK","Revisar"))
A40: Caso A · Baja · Agua de enfriamiento | B40: Normal | C40: Velocidad del fluido aguas abajo | D40: m/s | E40: 2.29 | H40: =IF(F40="","",(F40-E40)/E40) | I40: =IF(Tolerancias!C21="","",Tolerancias!C21) | J40: =IF(OR(F40="",I40=""),"",IF(ABS(H40)*100<=I40,"OK","Revisar"))
...

Sheet Tolerancias
A1: Clave | B1: Variable | C1: Tolerancia | D1: Unidad | E1: Comentario
A2: Cv | B2: Coeficiente de flujo Cv | C2: 2 | D2: % | E2: Con los mismos FL, xT, Fd y diámetros.
A3: Y | B3: Factor de expansión Y | C3: 1 | D3: % | E3: Gas, vapor y steam.
A4: dPchoked | B4: ΔP de flujo estrangulado | C4: 2 | D4: %
A5: FP | B5: Factor de tuberías Fp | C5: 1 | D5: % | E5: Con reductores la norma itera; hasta 1 % es normal.
A6: dP | B6: Presión diferencial | C6: 0.5 | D6: % | E6: Debe coincidir: es dato de entrada.
A7: apertura | B7: Apertura estimada | C7: 5 | D7: puntos | E7: Depende de la curva de cada fabricante; informativa.
A8: Lp | B8: Ruido LpA a 1 m (líquido) | C8: 3 | D8: dB | E8: IEC 60534-8-4; entre implementaciones 1 a 3 dB es normal.
A9: Lp_g | B9: Ruido LpA a 1 m (gas) | C9: 3 | D9: dB | E9: IEC 60534-8-3; verificar que el otro software use la misma norma.
A10: Ma_valvula | B10: Mach en la salida de la válvula | C10: 5 | D10: % | E10: Depende del área de salida considerada.
A11: v_valvula | B11: Velocidad en la salida de la válvula | C11: 5 | D11: %
A12: sobrecalentamiento2 | B12: Sobrecalentamiento a P2 | C12: 2 | D12: °C | E12: Steam (IAPWS-95).
A13: Kapp | B13: Coeficiente de cavitación Kapp | C13: 1 | D13: % | E13: Dato derivado de ΔP, P1 y Pv.
A14: xFzp1 | B14: Inicio de cavitación xFzp1 | C14: 5 | D14: % | E14: IEC 60534-8-4; muchos programas no lo informan.
A15: FLP | B15: Factor FLp | C15: 1 | D15: % | E15: Con reductores.
A16: dPcav | B16: ΔP de cavitación | C16: 3 | D16: % | E16: Depende de Kc o xFz.
A17: rho | B17: Densidad de entrada | C17: 1 | D17: % | E17: Propiedades del fluido.
A18: rho2 | B18: Densidad de salida | C18: 2 | D18: % | E18: Steam.
A19: xTP | B19: xTP | C19: 1 | D19: % | E19: Con reductores.
A20: v1 | B20: Velocidad aguas arriba (líquido) | C20: 3 | D20: %
A21: v2 | B21: Velocidad aguas abajo (líquido) | C21: 3 | D21: %
A22: v2_g | B22: Velocidad aguas abajo (gas) | C22: 3 | D22: %
A23: Rev | B23: Número de Reynolds | E23: Informativo: cada software usa una convención; no cambia el Cv si Rev > 10 000.

Sheet Materiales y empaques
A1: Caso | B1: Componente | C1: Recomendación N25 Valves Sizing | D1: Especificación de su empresa o del fabricante | E1: ¿Coincide? | F1: Observaciones
A2: Caso A · Baja · Agua de enfriamiento | B2: Cuerpo | C2: ASTM A216 WCB — acero al carbono fundido · 150 HB
A3: Caso A · Baja · Agua de enfriamiento | B3: Tapa / brida de eje | C3: ASTM A216 WCB — acero al carbono fundido · 150 HB
A4: Caso A · Baja · Agua de enfriamiento | B4: Anillo de asiento | C4: 17-4PH H900 (40–47 HRC) · 44 HRC (≈ 411 HB)
A5: Caso A · Baja · Agua de enfriamiento | B5: Cojinetes del eje | C5: 17-4PH H1150D (≤ 33 HRC, NACE) · 30 HRC (≈ 286 HB)
A6: Caso A · Baja · Agua de enfriamiento | B6: Bola / disco / obturador | C6: 17-4PH H1075 (≈ 33–38 HRC) · 35 HRC (≈ 327 HB)
A7: Caso A · Baja · Agua de enfriamiento | B7: Eje | C7: Inoxidable 316 / 316L (A479, A276) · 150 HB
A8: Caso A · Baja · Agua de enfriamiento | B8: Empaquetadura | C8: Anillos en V de PTFE, simple, con resorte
A9: Caso A · Baja · Agua de enfriamiento | B9: Tipo de bonete | C9: Estándar (prensaestopas del eje)
A10: Caso A · Baja · Agua de enfriamiento | B10: Emisión fugitiva | C10: estándar
A11: Caso A · Baja · Agua de enfriamiento | B11: Servicio agrio / norma | C11: No · No aplica
A12: Caso B · Media · Vapor sobrecalentado | B12: Cuerpo | C12: ASTM A217 WC6 — acero 1¼Cr-½Mo fundido · 170 HB
A13: Caso B · Media · Vapor sobrecalentado | B13: Bonete | C13: ASTM A217 WC6 — acero 1¼Cr-½Mo fundido · 170 HB
... A31: Caso C · Alta · Agua producida agria | B31: Servicio agrio / norma | C31: Sí · ISO 15156 / MR0175

Sheet Casos propios
A1: Caso / tag | B1: Fluido | C1: Condición | D1: Variable | E1: Unidad | F1: N25 Valves Sizing | G1: Software de referencia | H1: Nombre del software | I1: Diferencia % | J1: Archivo .valvula | K1: Observaciones
I2: =IF(OR(F2="",G2=""),"",(G2-F2)/F2)
I3: =IF(OR(F3="",G3=""),"",(G3-F3)/F3)
I4: =IF(OR(F4="",G4=""),"",(G4-F4)/F4)
I5: =IF(OR(F5="",G5=""),"",(G5-F5)/F5)
I6: =IF(OR(F6="",G6=""),"",(G6-F6)/F6)
I7: =IF(OR(F7="",G7=""),"",(G7-F7)/F7)
I8: =IF(OR(F8="",G8=""),"",(G8-F8)/F8)
I9: =IF(OR(F9="",G9=""),"",(G9-F9)/F9)
I10: =IF(OR(F10="",G10=""),"",(G10-F10)/F10)
I11: =IF(OR(F11="",G11=""),"",(G11-F11)/F11)
I12: =IF(OR(F12="",G12=""),"",(G12-F12)/F12)
I13: =IF(OR(F13="",G13=""),"",(G13-F13)/F13)
... I101: =IF(OR(F101="",G101=""),"",(G101-F101)/F101)

Sheet Hallazgos
A1: N° | B1: Fecha | C1: Tipo | D1: Pantalla o documento | E1: Descripción | F1: Cómo reproducirlo | G1: Gravedad | H1: Captura / archivo
A2: 1
A3: 2
A4: 3
A5: 4
A6: 5
A7: 6
A8: 7
A9: 8
A10: 9
A11: 10
A12: 11
A13: 12
... A51: 50
